<?xml version="1.0" ?>
<!-- =================================================================================== -->
<!-- |    This document was autogenerated by xacro from hector_multisensor_head_standalone.urdf.xacro | -->
<!-- |    EDITING THIS FILE BY HAND IS NOT RECOMMENDED                                 | -->
<!-- =================================================================================== -->
<robot name="hector_multisensor_head" xmlns:xacro="http://ros.org/wiki/xacro">
  <!--<xacro:include filename="$(find thor_mang_description)/urdf/helper_macros.urdf.xacro.xml" />-->
  <!--
     The asus_camera_model macro only adds the model, it does not also add
     the openni gazebo plugin. See the 'asus_camera' macro below for that
    -->
  <!--
     The asus_camera macro only adds the model, and also adds
     the openni gazebo plugin.
    -->
  <link name="world"/>
  <joint name="fixed1" type="fixed">
    <parent link="world"/>
    <child link="base"/>
    <origin rpy="0 0 0" xyz="0.0 0.0 0.5"/>
  </joint>
  <link name="base">
    <origin rpy="0 0 0" xyz="0.0 0.0 0.0"/>
    <visual>
      <geometry>
        <cylinder length="1" radius="0.045"/>
      </geometry>
    </visual>
    <collision>
      <geometry>
        <cylinder length="1" radius="0.045"/>
      </geometry>
    </collision>
  </link>
  <joint name="fixed2" type="fixed">
    <parent link="base"/>
    <child link="head_link"/>
    <origin rpy="0 0 0" xyz="0.0 0.0 0.5"/>
  </joint>
  <link name="head_link">
    <inertial>
      <origin rpy="0 0 0" xyz="0.0 0.0 0"/>
      <mass value="0.1"/>
      <inertia ixx="9e-06" ixy="0.0" ixz="0.0" iyy="9e-06" iyz="0.0" izz="9e-06"/>
    </inertial>
    <collision name="collision">
      <origin rpy="1.5707963268 0.0 1.5707963268" xyz="0.0 0.0 0"/>
      <geometry>
        <mesh filename="package://hector_components_description/meshes/hector_multisensor_head/multisensor_head_collision.stl" scale="0.001 0.001 0.001"/>
      </geometry>
    </collision>
    <visual>
      <origin rpy="1.5707963268 0.0 1.5707963268" xyz="0.0 0.0 0"/>
      <geometry>
        <mesh filename="package://hector_components_description/meshes/hector_multisensor_head/multisensor_head.stl" scale="0.001 0.001 0.001"/>
      </geometry>
    </visual>
  </link>
  <joint name="head_lidar_spinning_joint" type="continuous">
    <origin rpy="0 0 0" xyz="0.061 0.0 0.134"/>
    <origin rpy="1.5707963268 0.0 1.5707963268" xyz="0.0 0.0 0"/>
    <parent link="head_link"/>
    <child link="head_lidar_mount_link"/>
    <axis rpy="0 0 0" xyz="1 0 0"/>
    <limit effort="1000" velocity="100"/>
    <joint_properties damping="500.0" friction="200.0"/>
  </joint>
  <link name="head_lidar_mount_link">
    <xacro:inertial_sphere_with_pose_macro diameter="0.03" mass="1.1">
      <origin rpy="0 0 0" xyz="0.0 0.0 0.0"/>
    </xacro:inertial_sphere_with_pose_macro>
  </link>
  <joint name="head_link_hokuyo_laser_joint" type="fixed">
    <!-- CHANGE HERE FOR LIDAR MODEL ERROR -->
    <origin rpy="0 0.1 0" xyz="0 0 0"/>
    <parent link="head_lidar_mount_link"/>
    <child link="head_link_hokuyo_laser_frame"/>
  </joint>
  <link name="head_link_hokuyo_laser_frame">
    <inertial>
      <mass value="0.270"/>
      <origin rpy="0 0 0" xyz="0 0.05 0.05"/>
      <inertia ixx="2.632e-4" ixy="0" ixz="0" iyy="2.632e-4" iyz="0" izz="1.62e-4"/>
    </inertial>
    <visual>
      <origin rpy="0 0 0" xyz="0 0 0"/>
      <geometry>
        <mesh filename="package://hector_sensors_description/meshes/hokuyo_utm30lx/hokuyo_utm_30lx.dae"/>
      </geometry>
    </visual>
    <collision>
      <origin rpy="0 0 0" xyz="0 0 -0.0115"/>
      <geometry>
        <box size="0.058 0.058 0.087"/>
        <!--<mesh filename="package://hector_sensors_description/meshes/hokuyo_utm30lx/hokuyo_utm_30lx.stl"/>-->
      </geometry>
    </collision>
  </link>
  <gazebo reference="head_link_hokuyo_laser_frame">
    <sensor name="head_link_hokuyo_laser" type="ray">
      <always_on>true</always_on>
      <update_rate>40</update_rate>
      <pose>0 0 0 0 0 0</pose>
      <visualize>false</visualize>
      <ray>
        <scan>
          <horizontal>
            <samples>1040</samples>
            <resolution>1</resolution>
            <min_angle>2.26892802759</min_angle>
            <max_angle>-2.26892802759</max_angle>
          </horizontal>
        </scan>
        <range>
          <min>0.08</min>
          <max>30.0</max>
          <resolution>0.01</resolution>
        </range>
      </ray>
      <plugin filename="libgazebo_ros_laser.so" name="gazebo_ros_head_link_hokuyo_laser_controller">
        <gaussianNoise>0.005</gaussianNoise>
        <hokuyoMinIntensity>2000</hokuyoMinIntensity>
        <alwaysOn>true</alwaysOn>
        <updateRate>40</updateRate>
        <topicName>/head_lidar/scan</topicName>
        <frameName>head_link_hokuyo_laser_frame</frameName>
      </plugin>
    </sensor>
  </gazebo>
  <transmission name="head_lidar_spinning_joint_transmission">
    <type>transmission_interface/SimpleTransmission</type>
    <joint name="head_lidar_spinning_joint">
      <hardwareInterface>EffortJointInterface</hardwareInterface>
    </joint>
    <actuator name="head_lidar_spinning_joint_motor">
      <hardwareInterface>EffortJointInterface</hardwareInterface>
      <mechanicalReduction>1</mechanicalReduction>
    </actuator>
  </transmission>
  <gazebo reference="head_lidar_spinning_joint">
    <implicitSpringDamper>1</implicitSpringDamper>
  </gazebo>
  <joint name="head_cam_joint" type="fixed">
    <origin rpy="0 0 0" xyz="0.0385 0.0 0.2385"/>
    <parent link="head_link"/>
    <child link="head_cam_link"/>
  </joint>
  <link name="head_cam_link">
    <inertial>
      <mass value="0.200"/>
      <origin rpy="0 0 0" xyz="0 0 0"/>
      <inertia ixx="5.8083e-4" ixy="0" ixz="0" iyy="3.0833e-5" iyz="0" izz="5.9083e-4"/>
    </inertial>
    <visual>
      <origin rpy="0 0 0" xyz="0 0 0"/>
      <geometry>
        <mesh filename="package://hector_sensors_description/meshes/asus_camera/asus_camera_simple.dae"/>
      </geometry>
    </visual>
    <!--        
       <collision>
          <origin xyz="0 0 0" rpy="0 0 0" />
          <geometry>
            <box size="0.035 0.185 0.025"/>
          </geometry>
        </collision>
        -->
    <collision>
      <origin rpy="0 0 0" xyz="0 0 0"/>
      <geometry>
        <mesh filename="package://hector_sensors_description/meshes/asus_camera/asus_camera_simple.dae"/>
      </geometry>
    </collision>
  </link>
  <joint name="head_cam_depth_joint" type="fixed">
    <origin rpy="0 0 0" xyz="0.0 0.049 0.0"/>
    <parent link="head_cam_link"/>
    <child link="head_cam_depth_frame"/>
  </joint>
  <link name="head_cam_depth_frame"/>
  <joint name="head_cam_depth_optical_joint" type="fixed">
    <origin rpy="-1.5707963268 0.0 -1.5707963268" xyz="0 0 0"/>
    <parent link="head_cam_depth_frame"/>
    <child link="head_cam_depth_optical_frame"/>
  </joint>
  <link name="head_cam_depth_optical_frame"/>
  <joint name="head_cam_rgb_joint" type="fixed">
    <origin rpy="0 0 0" xyz="0.0 0.022 0.0"/>
    <parent link="head_cam_link"/>
    <child link="head_cam_rgb_frame"/>
  </joint>
  <link name="head_cam_rgb_frame"/>
  <joint name="head_cam_rgb_optical_joint" type="fixed">
    <origin rpy="-1.5707963268 0.0 -1.5707963268" xyz="0 0 0"/>
    <parent link="head_cam_rgb_frame"/>
    <child link="head_cam_rgb_optical_frame"/>
  </joint>
  <link name="head_cam_rgb_optical_frame"/>
  <!-- ASUS Xtion PRO camera for simulation -->
  <gazebo reference="head_cam_depth_frame">
    <sensor name="head_cam" type="depth">
      <update_rate>20</update_rate>
      <camera>
        <horizontal_fov>1.09606677025</horizontal_fov>
        <image>
          <format>R8G8B8</format>
          <width>640</width>
          <height>480</height>
        </image>
        <clip>
          <near>0.5</near>
          <far>9</far>
        </clip>
      </camera>
      <plugin filename="libgazebo_ros_openni_kinect.so" name="head_cam_camera_controller">
        <alwaysOn>true</alwaysOn>
        <updateRate>20</updateRate>
        <imageTopicName>head_cam/rgb/image_raw</imageTopicName>
        <cameraInfoTopicName>head_cam/rgb/camera_info</cameraInfoTopicName>
        <depthImageTopicName>head_cam/depth/image_raw</depthImageTopicName>
        <depthImageCameraInfoTopicName>head_cam/depth/camera_info</depthImageCameraInfoTopicName>
        <pointCloudTopicName>head_cam/depth/points</pointCloudTopicName>
        <frameName>head_cam_depth_optical_frame</frameName>
        <distortion_k1>0.0</distortion_k1>
        <distortion_k2>0.0</distortion_k2>
        <distortion_k3>0.0</distortion_k3>
        <distortion_t1>0.0</distortion_t1>
        <distortion_t2>0.0</distortion_t2>
      </plugin>
    </sensor>
  </gazebo>
  <!-- <gazebo reference="${name}_spinning_lidar_root_link"><material>Gazebo/Grey</material></gazebo><gazebo reference="${name}_spinning_lidar_spin_link"><material>Gazebo/Grey</material></gazebo> -->
  <gazebo>
    <plugin filename="libgazebo_ros_control.so" name="gazebo_ros_control">
      <robotNamespace>thor_mang</robotNamespace>
    </plugin>
  </gazebo>
</robot>

